<?xml version="0.0" ?>
<robot name="cube.urdf">
  <link name="baseLink">
    <contact>
      <lateral_friction value="2.0"/>
      <inertia_scaling value="3.0"/>
    </contact>
    <inertial>
      <origin rpy="0 0 0" xyz="0 0 0"/>
       <mass value=".05"/>
       <inertia ixx="1" ixy="0" ixz="0" iyy="1" iyz="0" izz="1"/>
    </inertial>
    <visual>
      <origin rpy="3.14 3.14 0" xyz="0 0 -0.1"/>
      <geometry>
        <mesh filename="model_new.obj" scale="0.8 0.8 0.6"/>
      </geometry>
       <material name="white">
        <color rgba="0.54 0.8 0 1"/>
      </material>
    </visual>
    <collision>
      <origin rpy="3.14 3.14 0" xyz="0 0 -0.1"/>
      <geometry>
        <mesh filename="model_new.obj" scale="0.8 0.8 0.6"/>
      </geometry>
    </collision>
  </link>
  <joint name="joint_baseLink_childA" type="prismatic">
    <parent link="baseLink"/>
    <child link="rear"/>
    <origin rpy="1.570 0 3.14" xyz="0.0 0.0 0.0"/>
    <axis xyz="0 1.0 0"/>
    <limit lower="0.0" upper="0.2" />
  </joint>

  <link name="down">
    <inertial>
      <origin rpy="0 0 0" xyz="0 0 0"/>
      <mass value="0.001"/>
      <inertia ixx="-4.46E-06" ixy="-4.55E-07" ixz="1.95E-06" iyy="-2.47E-06" iyz="8.51E-08" izz="2.17E-06"/>
    </inertial>
    <visual>
      <origin rpy="0 0 0" xyz="0 0 -0.05"/>
      <geometry>
        <box size=".28 .15 0.01"/>
      </geometry>
      <material name="green">
      </material> 
    </visual>
    <collision>
      <origin rpy="0 0 0" xyz="0 0 -0.05"/>
      <geometry>
        <box size=".28 .15 0.01"/>
      </geometry>
    </collision>
  </link>

  <link name="left">
    <inertial>
      <origin rpy="0 0 0" xyz="0 0 0"/>
      <mass value="0.001"/>
      <inertia ixx="-4.46E-06" ixy="-4.55E-07" ixz="1.95E-06" iyy="-2.47E-06" iyz="8.51E-08" izz="2.17E-06"/>
    </inertial>
    <visual>
      <origin rpy="0 0 0" xyz="0.135 0.0 0"/>
      <geometry>
        <box size=".01 .15 0.1"/>
      </geometry>
      <material name="green">
      </material> 
    </visual>
    <collision>
      <origin rpy="0 0 0" xyz="0.135 0 0"/>
      <geometry>
        <box size=".01 .15 0.1"/>
      </geometry>
    </collision>
  </link>

  <joint name="left_joint" type="fixed">
    <origin rpy="0 0 0" xyz="0 0 0"/>
    <parent link="down"/>
    <child link="left"/>
  </joint>

  <link name="right">
    <inertial>
      <mass value="0.001"/>
      <inertia ixx="-4.46E-06" ixy="-4.55E-07" ixz="1.95E-06" iyy="-2.47E-06" iyz="8.51E-08" izz="2.17E-06"/>
    </inertial>
    <visual>
      <origin rpy="0 0 0" xyz="-0.135 0.0 0"/>
      <geometry>
        <box size=".01 .15 0.1"/>
      </geometry>
      <material name="green">
      </material> 
    </visual>
    <collision>
      <origin rpy="0 0 0" xyz="-0.135 0 0"/>
      <geometry>
        <box size=".01 .15 0.1"/>
      </geometry>
    </collision>
  </link>

  <joint name="right_joint" type="fixed">
    <origin rpy="0 0 0" xyz="0 0 0"/>
    <parent link="down"/>
    <child link="right"/>
  </joint>

  <link name="front">
    <inertial>
      <mass value="0.001"/>
      <inertia ixx="-4.46E-06" ixy="-4.55E-07" ixz="1.95E-06" iyy="-2.47E-06" iyz="8.51E-08" izz="2.17E-06"/>
    </inertial>
    <visual>
      <origin rpy="0 0 0" xyz="0 0.0725 0"/>
      <geometry>
        <box size=".27 .01 0.1"/>
      </geometry>
      <material name="green">
      </material> 
    </visual>
    <collision>
      <origin rpy="0 0 0" xyz="0 0.0725 0"/>
      <geometry>
        <box size=".27 .01 0.1"/>
      </geometry>
    </collision>
  </link>

  <joint name="front_joint" type="fixed">
    <origin rpy="0 0 0" xyz="0 0 0"/>
    <parent link="down"/>
    <child link="front"/>
  </joint>

  <link name="rear">
    <inertial>
      <origin rpy="0 0 0" xyz="0 -0.0725 0"/>
      <mass value="0.001"/>
      <inertia ixx="-4.46E-06" ixy="-4.55E-07" ixz="1.95E-06" iyy="-2.47E-06" iyz="8.51E-08" izz="2.17E-06"/>
    </inertial>
    <visual>
      <origin rpy="0 0 0" xyz="0 -0.0725 0"/>
      <geometry>
        <box size=".27 .01 0.1"/>
      </geometry>
      <material name="green">
      </material> 
    </visual>
    <collision>
      <origin rpy="0 0 0" xyz="0 -0.0725 0"/>
      <geometry>
        <box size=".27 .01 0.1"/>
      </geometry>
    </collision>
  </link>

  <joint name="rear_joint" type="fixed">
    <origin rpy="0 0 0" xyz="0 0 0"/>
    <parent link="rear"/>
    <child link="down"/>
  </joint>


  <material name="panda_white">
    <color rgba="1. 1. 1. 1."/>
  </material>
  <material name="red">
    <color rgba="1.0 0. 0. 1.0"/>
  </material>
  <material name="blue">
    <color rgba="0. 0. 1. 1.0"/>
  </material>
  <material name="green">
    <color rgba="0. 1. 0. 1.0"/>
  </material>
<material name="Yellow">
  <color rgba="0.949 0.878 0.0392 1.0"/>
</material>
<material name="Blue">
  <color rgba="0.12156 0.3804 0.6745 1.0"/>
</material>
<material name="Red">
  <color rgba="0.9254901 0.243137 0.086274509 1.0"/>
</material>
</robot>

