<?xml version="1.0"?>
<robot name="book">
  <link name ="rb0">
    <visual>
      <origin xyz='0.126804 -0.046692 -0.124746' rpy='0.216949 -1.472020 -1.942373'/>
      <geometry>
        <mesh filename="package://articulated_objects_db/data/objects/book/meshes/book_bottom.dae"  scale="1 1 1" />
      </geometry>
    </visual>
  </link>
  <joint name="j_0_1" type="revolute">
    <parent link="rb0"/>
    <child link="rb1"/>
    <origin xyz="-0.0177468744444 0.0828859326016 -0.0231983870346" rpy="0 0 0 "/>
    <axis xyz="-0.0136715161651 0.0358929975763 0.999262118951"/>
    <limit effort="30" velocity="1.0" lower="-3.1416" upper="3.1416"/>
  </joint>
  <joint name="j_0_fixed" type="fixed">
    <parent link="rb1"/>
    <child link="rb1_marker"/>
      <origin xyz="-0.0478552688509 -0.199694573384 0.00642943110735" rpy="-1.54919398998 -0.0117697714579 2.44482313398"/>
    <limit effort="30" velocity="1.0" lower="-3.1416" upper="3.1416"/>
  </joint>
  <link name ="rb1">
  </link>
  <link name ="rb1_marker">
    <visual>
      <origin xyz='-0.033606 0.111992 -0.131134' rpy='-2.689532 -0.104439 -1.616204'/>
      <geometry>
        <mesh filename="package://articulated_objects_db/data/objects/book/meshes/book_top.dae"  scale="1 1 1" />
      </geometry>
    </visual>
  </link>
</robot>
