<?xml version="1.0"?>
<robot name="book">
  <link name ="rb0">
    <visual>
      <origin xyz='0.124599 -0.032295 -0.139641' rpy='-0.381872 -1.434270 -1.253276'/>
      <geometry>
        <mesh filename="package://articulated_objects_db/data/objects/book/meshes/book_bottom.dae"  scale="1 1 1" />
      </geometry>
    </visual>
  </link>
  <joint name="j_0_1" type="revolute">
    <parent link="rb0"/>
    <child link="rb1"/>
    <origin xyz="-0.0178475108059 0.0830259596699 -0.104886973761" rpy="0 0 0 "/>
    <axis xyz="0.0116820855415 0.0195133306668 0.999741345951"/>
    <limit effort="30" velocity="1.0" lower="-3.1416" upper="3.1416"/>
  </joint>
  <joint name="j_0_fixed" type="fixed">
    <parent link="rb1"/>
    <child link="rb1_marker"/>
      <origin xyz="-0.0399173662991 -0.20123964127 0.00394968654589" rpy="1.59426589408 0.0318340080446 1.38128013071"/>
    <limit effort="30" velocity="1.0" lower="-3.1416" upper="3.1416"/>
  </joint>
  <link name ="rb1">
  </link>
  <link name ="rb1_marker">
    <visual>
      <origin xyz='0.104927 -0.031305 0.080058' rpy='1.601578 -0.031979 1.722571'/>
      <geometry>
        <mesh filename="package://articulated_objects_db/data/objects/book/meshes/book_top.dae"  scale="1 1 1" />
      </geometry>
    </visual>
  </link>
</robot>
