<?xml version="0.0" ?>
<robot name="cube.urdf">
  <link name="top">
    <contact>
      <lateral_friction value="2.0"/>
      <inertia_scaling value="3.0"/>
    </contact>
    <inertial>
      <origin rpy="0 3.14 3.14" xyz="0 0 0"/>
       <mass value=".05"/>
       <inertia ixx="1" ixy="0" ixz="0" iyy="1" iyz="0" izz="1"/>
    </inertial>
    <visual>
      <origin rpy="0 3.14 3.14" xyz="0 0 0"/>
      <geometry>
        <mesh filename="drawer_new.obj" scale="0.6 0.5 0.5"/>
      </geometry>
       <material name="white">
        <color rgba="0.54 0.8 0 1"/>
      </material>
    </visual>
    <collision>
      <origin rpy="0 3.14 3.14" xyz="0 0 0"/>
      <geometry>
        <mesh filename="drawer_new.obj" scale="0.6 0.5 0.5"/>
      </geometry>
    </collision>
  </link>
  <joint name="joint_baseLink_childA" type="prismatic">
    <parent link="baseLink"/>
    <child link="top"/>
    <origin rpy="3.14 0 0" xyz="0.0 0 0.0"/>
    <axis xyz="0 0 -1"/>
    <limit lower="0.05" upper="0.3" />
  </joint>
  <link name="baseLink">
    <contact>
      <lateral_friction value="2.0"/>
      <inertia_scaling value="3.0"/>
    </contact>
    <inertial>
      <origin rpy="0 0 0" xyz="0 0 0"/>
       <mass value=".05"/>
       <inertia ixx="1" ixy="0" ixz="0" iyy="1" iyz="0" izz="1"/>
    </inertial>
    <visual>
      <origin rpy="3.14 3.14 0" xyz="0 0 -0.1"/>
      <geometry>
        <mesh filename="model_new.obj" scale="0.7 0.65 0.55"/>
      </geometry>
       <material name="white">
        <color rgba="0.54 0.8 0 1"/>
      </material>
    </visual>
    <collision>
      <origin rpy="3.14 3.14 0" xyz="0 0 -0.1"/>
      <geometry>
        <mesh filename="model_new.obj" scale="0.7 0.65 0.55"/>
      </geometry>
    </collision>
  </link>
</robot>

