<?xml version="1.0"?>
<robot name="book">
  <link name ="rb0">
    <visual>
      <origin xyz='0.127528 -0.021424 -0.126922' rpy='-0.049208 -1.379315 -1.552577'/>
      <geometry>
        <mesh filename="package://articulated_objects_db/data/objects/book/meshes/book_bottom.dae"  scale="1 1 1" />
      </geometry>
    </visual>
  </link>
  <joint name="j_0_1" type="revolute">
    <parent link="rb0"/>
    <child link="rb1"/>
    <origin xyz="-0.0127840336627 0.0963514984799 -0.107921289496" rpy="0 0 0 "/>
    <axis xyz="0.0778795231616 0.0208040311173 0.996745690817"/>
    <limit effort="30" velocity="1.0" lower="-3.1416" upper="3.1416"/>
  </joint>
  <joint name="j_0_fixed" type="fixed">
    <parent link="rb1"/>
    <child link="rb1_marker"/>
      <origin xyz="-0.036085312533 -0.212611250033 0.0068916262335" rpy="1.56680366634 -0.0173914329961 1.39385734846"/>
    <limit effort="30" velocity="1.0" lower="-3.1416" upper="3.1416"/>
  </joint>
  <link name ="rb1">
  </link>
  <link name ="rb1_marker">
    <visual>
      <origin xyz='0.112065 -0.028672 0.076906' rpy='1.674489 -0.030900 1.717519'/>
      <geometry>
        <mesh filename="package://articulated_objects_db/data/objects/book/meshes/book_top.dae"  scale="1 1 1" />
      </geometry>
    </visual>
  </link>
</robot>
