<?xml version="1.0" ?>
<!-- =================================================================================== -->
<!-- |    This document was autogenerated by xacro from panda_arm_hand.urdf.xacro      | -->
<!-- |    EDITING THIS FILE BY HAND IS NOT RECOMMENDED                                 | -->
<!-- =================================================================================== -->
<robot name="panda" xmlns:xacro="http://www.ros.org/wiki/xacro">
  <link name="base_link">
    <visual>
      <geometry>
        <mesh filename="/franka_panda/visual/link0.dae"/>
      </geometry>
      <material name="panda_white"/>
    </visual>
    <collision>
      <geometry>
        <mesh filename="/franka_panda/visual/link0.dae"/>
      </geometry>
      <material name="panda_white"/>
    </collision>

    <inertial>
      <mass value="0.0"/>
      <origin xyz="0.0 0.0 0.0"/>
      <inertia ixx="0.000380" ixy="0.000000" ixz="0.000000" iyx="0.000000" iyy="0.001110" iyz="0.000000" izx="0.000000" izy="0.000000" izz="0.001171"/>
    </inertial>

  </link>

  <link name="panda_link1">
    <visual>
      <geometry>
        <mesh filename="/franka_panda/visual/link1.dae"/>
      </geometry>
      <material name="panda_white"/>
    </visual>
    <collision>
      <geometry>
        <mesh filename="/franka_panda/visual/link1.dae"/>
      </geometry>
      <material name="panda_white"/>
    </collision>
  </link>
  <joint name="panda_joint1" type="revolute">
    <safety_controller k_position="100.0" k_velocity="40.0" soft_lower_limit="-2.8973" soft_upper_limit="2.8973"/>
    <origin rpy="0 0 0" xyz="0 0 0.333"/>
    <parent link="base_link"/>
    <child link="panda_link1"/>
    <axis xyz="0 0 1"/>
    <limit effort="87" lower="-2.9671" upper="2.9671" velocity="2.1750"/>
  </joint>
  <link name="panda_link2">
    <visual>
      <geometry>
        <mesh filename="/franka_panda/visual/link2.dae"/>
      </geometry>
      <material name="panda_white"/>
    </visual>
    <collision>
      <geometry>
        <mesh filename="/franka_panda/visual/link2.dae"/>
      </geometry>
      <material name="panda_white"/>
    </collision>
  </link>
  <joint name="panda_joint2" type="revolute">
    <safety_controller k_position="100.0" k_velocity="40.0" soft_lower_limit="-1.7628" soft_upper_limit="1.7628"/>
    <origin rpy="-1.57079632679 0 0" xyz="0 0 0"/>
    <parent link="panda_link1"/>
    <child link="panda_link2"/>
    <axis xyz="0 0 1"/>
    <limit effort="87" lower="-1.8326" upper="1.8326" velocity="2.1750"/>
  </joint>
  <link name="panda_link3">
    <visual>
      <geometry>
        <mesh filename="/franka_panda/visual/link3.dae"/>
      </geometry>
      <material name="panda_white"/>
    </visual>
    <collision>
      <geometry>
        <mesh filename="/franka_panda/visual/link3.dae"/>
      </geometry>
      <material name="panda_white"/>
    </collision>
  </link>
  <joint name="panda_joint3" type="revolute">
    <safety_controller k_position="100.0" k_velocity="40.0" soft_lower_limit="-2.8973" soft_upper_limit="2.8973"/>
    <origin rpy="1.57079632679 0 0" xyz="0 -0.316 0"/>
    <parent link="panda_link2"/>
    <child link="panda_link3"/>
    <axis xyz="0 0 1"/>
    <limit effort="87" lower="-2.9671" upper="2.9671" velocity="2.1750"/>
  </joint>
  <link name="panda_link4">
    <visual>
      <geometry>
        <mesh filename="/franka_panda/visual/link4.dae"/>
      </geometry>
      <material name="panda_white"/>
    </visual>
    <collision>
      <geometry>
        <mesh filename="/franka_panda/visual/link4.dae"/>
      </geometry>
      <material name="panda_white"/>
    </collision>
  </link>
  <joint name="panda_joint4" type="revolute">
    <safety_controller k_position="100.0" k_velocity="40.0" soft_lower_limit="-3.0718" soft_upper_limit="-0.0698"/>
    <origin rpy="1.57079632679 0 0" xyz="0.0825 0 0"/>
    <parent link="panda_link3"/>
    <child link="panda_link4"/>
    <axis xyz="0 0 1"/>
    <limit effort="87" lower="-3.1416" upper="0.0" velocity="2.1750"/>
  </joint>
  <link name="panda_link5">
    <visual>
      <geometry>
        <mesh filename="/franka_panda/visual/link5.dae"/>
      </geometry>
      <material name="panda_white"/>
    </visual>
    <collision>
      <geometry>
        <mesh filename="/franka_panda/visual/link5.dae"/>
      </geometry>
      <material name="panda_white"/>
    </collision>
  </link>
  <joint name="panda_joint5" type="revolute">
    <safety_controller k_position="100.0" k_velocity="40.0" soft_lower_limit="-2.8973" soft_upper_limit="2.8973"/>
    <origin rpy="-1.57079632679 0 0" xyz="-0.0825 0.384 0"/>
    <parent link="panda_link4"/>
    <child link="panda_link5"/>
    <axis xyz="0 0 1"/>
    <limit effort="12" lower="-2.9671" upper="2.9671" velocity="2.6100"/>
  </joint>
  <link name="panda_link6">
    <visual>
      <geometry>
        <mesh filename="/franka_panda/visual/link6.dae"/>
      </geometry>
#      <material name="panda_white"/>
    </visual>
    <collision>
      <geometry>
        <mesh filename="/franka_panda/visual/link6.dae"/>
      </geometry>
      <material name="panda_white"/>
    </collision>
  </link>
  <joint name="panda_joint6" type="revolute">
    <safety_controller k_position="100.0" k_velocity="40.0" soft_lower_limit="-0.0175" soft_upper_limit="3.7525"/>
    <origin rpy="1.57079632679 0 0" xyz="0 0 0"/>
    <parent link="panda_link5"/>
    <child link="panda_link6"/>
    <axis xyz="0 0 1"/>
    <limit effort="12" lower="-0.0873" upper="3.8223" velocity="2.6100"/>
  </joint>
  <link name="panda_link7">
    <visual>
      <geometry>
        <mesh filename="/franka_panda/visual/link7.dae"/>
      </geometry>
      <material name="panda_white"/>
    </visual>
    <collision>
      <geometry>
        <mesh filename="/franka_panda/visual/link7.dae"/>
      </geometry>
      <material name="panda_white"/>
    </collision>
  </link>
  <joint name="panda_joint7" type="revolute">
    <safety_controller k_position="100.0" k_velocity="40.0" soft_lower_limit="-2.8973" soft_upper_limit="2.8973"/>
    <origin rpy="1.57079632679 0 0" xyz="0.088 0 0"/>
    <parent link="panda_link6"/>
    <child link="panda_link7"/>
    <axis xyz="0 0 1"/>
    <limit effort="12" lower="-2.9671" upper="2.9671" velocity="2.6100"/>
  </joint>
  <link name="panda_link8"/>

  <joint name="panda_joint8" type="fixed">
    <origin rpy="0 0 0" xyz="0 0 0.107"/>
    <parent link="panda_link7"/>
    <child link="panda_link8"/>
    <axis xyz="0 0 0"/>
  </joint>

  <joint name="panda_robotiq_coupling" type="fixed">
    <origin rpy="0 0 0" xyz="0 0 0"/>
    <parent link="panda_link8"/>
    <child link="robotiq_85_coupling_link"/>
    <axis xyz="0 0 0"/>
  </joint>

  <link name="robotiq_85_coupling_link">
    <visual>
      <geometry>
        <mesh filename="robotiq_2f_85/visual/robotiq_gripper_couplingvn.obj"/>
      </geometry>
      <material name="dark black"/>
    </visual>
    <collision>
      <geometry>
        <mesh filename="robotiq_2f_85/visual/robotiq_gripper_couplingvn.obj"/>
      </geometry>
    </collision>
  </link>

  <joint name="robotiq_85_base_joint" type="fixed">
    <parent link="robotiq_85_coupling_link"/>
    <child link="robotiq_85_base_link"/>
    <origin rpy="0 0 0" xyz="0 0 0"/>
  </joint>

  <link name="robotiq_85_base_link">
    <visual>
      <geometry>
        <mesh filename="robotiq_2f_85/visual/robotiq_arg2f_85_base_linkvn.obj"/>
      </geometry>
      <material name="Black"/>
    </visual>
    <collision>
      <geometry>
        <mesh filename="robotiq_2f_85/visual/robotiq_arg2f_85_base_linkvn.obj"/>
      </geometry>
    </collision>
      <inertial>
        <origin xyz="8.625E-08 -4.6583E-06 0.03145" rpy="0 0 0" />
        <mass value="0.22652" />
        <inertia ixx="0.00020005" ixy="-4.2442E-10" ixz="-2.9069E-10" iyy="0.00017832" iyz="-3.4402E-08" izz="0.00013478" />
      </inertial>
  </link>

  <joint name="robotiq_85_left_knuckle_joint" type="revolute">
    <parent link="robotiq_85_base_link"/>
    <child link="robotiq_85_left_knuckle_link"/>
    <axis xyz="1 0 0"/>
    <origin rpy="0 0.0 3.1415926" xyz="0 -0.0306011 0.054904"/>
    <limit lower="0" upper="0.81" velocity="100.0"/>
  </joint>
  <joint name="robotiq_85_right_knuckle_joint" type="revolute">
    <parent link="robotiq_85_base_link"/>
    <child link="robotiq_85_right_knuckle_link"/>
    <axis xyz="1 0 0"/>
    <origin rpy="0.0 0.0 0" xyz="0 0.0306011 0.054904"/>
    <limit lower="0" upper="0.81" velocity="100.0"/>
  </joint>

  <link name="robotiq_85_left_knuckle_link">
    <visual>
      <geometry>
        <mesh filename="robotiq_2f_85/visual/robotiq_arg2f_85_outer_knucklevn.obj"/>
      </geometry>
    <material name="Black"/>
    </visual>
    <collision>
      <geometry>
        <mesh filename="robotiq_2f_85/visual/robotiq_arg2f_85_outer_knucklevn.obj"/>
      </geometry>
    </collision>
    <!--<inertial>
        <origin xyz="-0.000200000000003065 0.0199435877845359 0.0292245259211331" rpy="0 0 0" />
        <mass value="0.00853198276973456" />
        <inertia ixx="2.89328108496468E-06" ixy="-1.57935047237397E-19" ixz="-1.93980378593255E-19" iyy="1.86719750325683E-06" iyz="-1.21858577871576E-06" izz="1.21905238907251E-06" />
    </inertial>-->
  </link>

  <link name="robotiq_85_right_knuckle_link">
    <visual>
      <geometry>
        <mesh filename="robotiq_2f_85/visual/robotiq_arg2f_85_outer_knucklevn.obj"/>
      </geometry>
      <material name="Black"/>
    </visual>
    <collision>
      <geometry>
        <mesh filename="robotiq_2f_85/visual/robotiq_arg2f_85_outer_knucklevn.obj"/>
      </geometry>
    </collision>
    <!--<inertial>
        <origin xyz="-0.000200000000003065 0.0199435877845359 0.0292245259211331" rpy="0 0 0" />
        <mass value="0.00853198276973456" />
        <inertia ixx="2.89328108496468E-06" ixy="-1.57935047237397E-19" ixz="-1.93980378593255E-19" iyy="1.86719750325683E-06" iyz="-1.21858577871576E-06" izz="1.21905238907251E-06" />
    </inertial>-->
  </link>


  <joint name="robotiq_85_left_finger_joint" type="fixed">
    <parent link="robotiq_85_left_knuckle_link"/>
    <child link="robotiq_85_left_finger_link"/>
    <origin rpy="0 0 0" xyz="0 0.0315 -0.0041"/>
    <limit lower="-3.14" upper="3.14" velocity="100.0"/>
  </joint>
  <joint name="robotiq_85_right_finger_joint" type="fixed">
    <parent link="robotiq_85_right_knuckle_link"/>
    <child link="robotiq_85_right_finger_link"/>
    <origin rpy="0 0 0" xyz="0 0.0315 -0.0041"/>
    <limit lower="-3.14" upper="3.14" velocity="100.0"/>
  </joint>

  <link name="robotiq_85_left_finger_link">
    <visual>
      <geometry>
        <mesh filename="robotiq_2f_85/visual/robotiq_arg2f_85_outer_fingervn.obj"/>
      </geometry>
      <material name="Black"/>
    </visual>
    <collision>
      <geometry>
        <mesh filename="robotiq_2f_85/visual/robotiq_arg2f_85_outer_fingervn.obj"/>
      </geometry>
    </collision>
    <!--<inertial>
      <mass value="0.027309"/>
      <origin xyz="0.0 0.0 0.0"/>
      <inertia ixx="0.000003" ixy="-0.000002" ixz="0.000000" iyx="-0.000002" iyy="0.000021" iyz="0.000000" izx="0.000000" izy="0.000000" izz="0.000020"/>
    </inertial>-->
  </link>
  <link name="robotiq_85_right_finger_link">
    <visual>
      <geometry>
        <mesh filename="robotiq_2f_85/visual/robotiq_arg2f_85_outer_fingervn.obj"/>
      </geometry>
      <material name="Black"/>
    </visual>
    <collision>
      <geometry>
        <mesh filename="robotiq_2f_85/visual/robotiq_arg2f_85_outer_fingervn.obj"/>
      </geometry>
    </collision>
    <!--<inertial>
      <mass value="0.027309"/>
      <origin xyz="0.0 0.0 0.0"/>
      <inertia ixx="0.000003" ixy="-0.000002" ixz="0.000000" iyx="-0.000002" iyy="0.000021" iyz="0.000000" izx="0.000000" izy="0.000000" izz="0.000020"/>
    </inertial>-->
  </link>

<joint name="robotiq_85_left_inner_knuckle_joint" type="revolute">
    <parent link="robotiq_85_base_link"/>
    <child link="robotiq_85_left_inner_knuckle_link"/>
    <axis xyz="1 0 0"/>
    <origin rpy="0 0.0 0" xyz="0 0.0127 0.06142"/>
    <limit lower="0" upper="0.8757" velocity="100.0"/>
  </joint>
  <joint name="robotiq_85_right_inner_knuckle_joint" type="revolute">
    <parent link="robotiq_85_base_link"/>
    <child link="robotiq_85_right_inner_knuckle_link"/>
    <axis xyz="1 0 0"/>
    <origin rpy="0 0 3.1415926" xyz="0 -0.0127 0.06142"/>
    <limit lower="0" upper="0.8757" velocity="100.0"/>
  </joint>
  <link name="robotiq_85_left_inner_knuckle_link">
    <visual>
      <geometry>
        <mesh filename="robotiq_2f_85/visual/robotiq_arg2f_85_inner_knucklevn.obj"/>
      </geometry>
      <material name="Black"/>
    </visual>
    <collision>
      <geometry>
        <mesh filename="robotiq_2f_85/visual/robotiq_arg2f_85_inner_knucklevn.obj"/>
      </geometry>
    </collision>
    <!--<inertial>
      <mass value="0.029951"/>
      <origin xyz="0.0 0.0 0.0"/>
      <inertia ixx="0.000039" ixy="0.000000" ixz="0.000000" iyx="0.000000" iyy="0.000005" iyz="0.000000" izx="0.000000" izy="0.000000" izz="0.000035"/>
    </inertial>-->
  </link>
  <link name="robotiq_85_right_inner_knuckle_link">
    <visual>
     <geometry>
        <mesh filename="robotiq_2f_85/visual/robotiq_arg2f_85_inner_knucklevn.obj"/>
      </geometry>
      <material name="Black"/>
    </visual>
    <collision>
     <geometry>
        <mesh filename="robotiq_2f_85/visual/robotiq_arg2f_85_inner_knucklevn.obj"/>
      </geometry>
    </collision>
    <!--<inertial>
      <mass value="0.029951"/>
      <origin xyz="0.0 0.0 0.0"/>
      <inertia ixx="0.000039" ixy="0.000000" ixz="0.000000" iyx="0.000000" iyy="0.000005" iyz="0.000000" izx="0.000000" izy="0.000000" izz="0.000035"/>
    </inertial>-->
  </link>

  <joint name="robotiq_85_left_finger_tip_joint" type="revolute">
    <parent link="robotiq_85_left_finger_link"/>
    <child link="robotiq_85_left_finger_tip_link"/>
    <axis xyz="1 0 0"/>
    <origin rpy="0.0 0.0 0.0" xyz="0 0.0061 0.0471"/>
    <limit lower="0" upper="-0.8" velocity="100.0"/>
  </joint>
  <joint name="robotiq_85_right_finger_tip_joint" type="revolute">
    <parent link="robotiq_85_right_finger_link"/>
    <child link="robotiq_85_right_finger_tip_link"/>
    <axis xyz="1 0 0"/>
    <origin rpy="0.0 0.0 0.0" xyz="0 0.0061 0.0471"/>
    <limit lower="0" upper="-0.8" velocity="100.0"/>
  </joint>

  <link name="robotiq_85_left_finger_tip_link">
    <contact>
      <lateral_friction value="2.0"/>
      <spinning_friction value="0.1"/>
    </contact>
    <visual>
      <geometry>
        <mesh filename="robotiq_2f_85/visual/robotiq_arg2f_85_inner_fingervn.obj"/>
      </geometry>
      <material name="Gray"/>
    </visual>
    <collision>
      <geometry>
        <mesh filename="robotiq_2f_85/visual/robotiq_arg2f_85_inner_fingervn.obj"/>
      </geometry>
    </collision>
    <!--<inertial>
      <mass value="0.019555"/>
      <origin xyz="0.0 0.0 0.0"/>
      <inertia ixx="0.000002" ixy="0.000000" ixz="0.000000" iyx="0.000000" iyy="0.000005" iyz="0.000000" izx="0.000000" izy="0.000000" izz="0.000006"/>
    </inertial> -->
  </link>
  <link name="robotiq_85_right_finger_tip_link">
    <contact>
      <lateral_friction value="2.0"/>
      <spinning_friction value="0.1"/>
    </contact>
    <visual>
      <geometry>
        <mesh filename="robotiq_2f_85/visual/robotiq_arg2f_85_inner_fingervn.obj"/>
      </geometry>
      <material name="Gray"/>
    </visual>
    <collision>
      <geometry>
        <mesh filename="robotiq_2f_85/visual/robotiq_arg2f_85_inner_fingervn.obj"/>
      </geometry>
    </collision>
    <!--<inertial>
      <mass value="0.019555"/>
      <origin xyz="0.0 0.0 0.0"/>
      <inertia ixx="0.000002" ixy="0.000000" ixz="0.000000" iyx="0.000000" iyy="0.000005" iyz="0.000000" izx="0.000000" izy="0.000000" izz="0.000006"/>
    </inertial>-->
  </link>

    <joint name="robotiq_2f_85_left_inner_finger_pad_joint" type="fixed">
      <origin xyz="0 -0.0220203446692936 0.03242" rpy="0 0 0"/>
      <parent link="robotiq_85_left_finger_tip_link" />
      <child link="robotiq_2f_85_left_inner_finger_pad" />
      <axis xyz="0 0 1" />
    </joint>

    <joint name="robotiq_2f_85_right_inner_finger_pad_joint" type="fixed">
      <origin xyz="0 -0.0220203446692936 0.03242" rpy="0 0 0"/>
      <parent link="robotiq_85_right_finger_tip_link" />
      <child link="robotiq_2f_85_right_inner_finger_pad" />
      <axis xyz="0 0 1" />
    </joint>

    <link name="robotiq_2f_85_left_inner_finger_pad">
      <visual>
        <origin xyz="0 0 0" rpy="0 0 0" />
        <geometry>
          <box size="0.022 0.00635 0.0375"/>
        </geometry>
        <material name="">
          <color rgba="0.9 0.9 0.9 1" />
        </material>
      </visual>
      <collision>
        <origin xyz="0 0 0" rpy="0 0 0" />
        <geometry>
           <box size="0.022 0.00635 0.0375"/>
        </geometry>
        <material name="">
          <color rgba="0.9 0.9 0.9 1" />
        </material>
      </collision>
    </link>


    <link name="robotiq_2f_85_right_inner_finger_pad">
      <visual>
        <origin xyz="0 0 0" rpy="0 0 0" />
        <geometry>
          <box size="0.022 0.00635 0.0375"/>
        </geometry>
        <material name="">
          <color rgba="0.9 0.9 0.9 1" />
        </material>
      </visual>
      <collision>
        <origin xyz="0 0 0" rpy="0 0 0" />
        <geometry>
           <box size="0.022 0.00635 0.0375"/>
        </geometry>
        <material name="">
          <color rgba="0.9 0.9 0.9 1" />
        </material>
      </collision>
    </link>


<material name="panda_white">
    <color rgba="1. 1. 1. 1."/>
  </material>
  <material name="dark black">
    <color rgba="0.1 0.1 0.1 1.0"/>
  </material>
  <material name="Black">
    <color rgba="0.1 0.1 0.1 1.0"/>
  </material>
  <material name="Gray">
    <color rgba="0.5 0.5 0.5 1.0"/>
  </material>
</robot>
